Workbook

Sheet Title_Abstract_Screening
A1: Study ID | B1: Registar/Database | C1: Keywords | D1: Title | E1: Authors | F1: Year | G1: Reviewer 1 Decision | H1: Reviewer 2 Decision | I1: Conflict | J1: Final Decision
A2: S01 | B2: arXiv | C2: low-resource languages survey ; NLP survey | D2: A Breadth-First Catalog of Text Processing, Speech Processing and Multimodal Research in South Asian Languages | E2: Gupta, Pranav | F2: 2024 | G2: Include | H2: Include | I2: No | J2: Include
A3: S02 | B3: ACM Digital Library | C3: knowledge graph construction; knowledge extraction; survey | D3: A Comprehensive Survey on Automatic Knowledge Graph Construction | E3: Zhong, Lingfeng; Wu, Jia; Li, Qian; Peng, Hao; Wu, Xindong | F3: 2023 | G3: Include | H3: Include | I3: No | J3: Include
A4: S03 | B4: ACLWeb | C4: relation classification; multilingual; low-resource languages; distant supervision | D4: A Data Bootstrapping Recipe for Low-Resource Multilingual Relation Classification | E4: Nag, Arijit; Samanta, Bidisha; Mukherjee, Animesh; Ganguly, Niloy; Chakrabarti, Soumen | F4: 2021 | G4: Include | H4: Include | I4: No | J4: Include
A5: S04 | B5: ACLWeb | C5: knowledge graphs; natural language processing; knowledge extraction; survey | D5: A Decade of Knowledge Graphs in Natural Language Processing: A Survey | E5: Schneider, Phillip; Schopf, Tim; Vladika, Juraj; Galkin, Mikhail; Simperl, Elena; Matthes, Florian | F5: 2022 | G5: Include | H5: Include | I5: No | J5: Include
A6: S05 | B6: ACM Digital Library | C6: anaphora resolution;low-resources; coreference; | D6: A Detailed Study on Anaphora Resolution System for Asian Languages | E6: Prajapati, Priyanka; Goyal, Vishal; Kaur, Kawaljit | F6: 2024 | G6: Include | H6: Include | I6: No | J6: Include
A7: S06 | B7: ACLWeb | C7: entity extraction; relation extraction | D7: A Frustratingly Easy Approach for Entity and Relation Extraction | E7: Zhong, Zexuan; Chen, Danqi | F7: 2021 | G7: Include | H7: Include | I7: No | J7: Include
A8: S07 | B8: ACLWeb | C8: knowledge graph construction; entity extraction; relation extraction | D8: A High Precision Pipeline for Financial Knowledge Graph Construction | E8: Elhammadi, Sarah; V.S. Lakshmanan, Laks; Ng, Raymond; Simpson, Michael; Huai, Baoxing; Wang, Zhefeng; Wang, Lanjun | F8: 2020 | G8: Include | H8: Include | I8: No | J8: Include
A9: S08 | B9: IEEE Xplore | C9: anaphora resolution; Nepali; machine learning; low-resource languages | D9: A Machine Learning Approach to Anaphora Resolution in Nepali Language | E9: Senapati, Apurbalal; Poudyal, Arun; Adhikary, Prithwiraj; Kaushar, Sahana; Mahajan, Anmol; Nath Saha, Baidya | F9: 2020 | G9: Include | H9: Include | I9: No | J9: Include
A10: S09 | B10: ACLWeb | C10: triple extraction; table filling; joint entity and relation extraction | D10: A Novel Global Feature-Oriented Relational Triple Extraction Model based on Table Filling | E10: Ren, Feiliang; Zhang, Longhui; Yin, Shujuan; Zhao, Xiaofeng; Liu, Shilei; Li, Bochao; Liu, Yaduo | F10: 2021 | G10: Exclude | H10: Include | I10: Yes | J10: Include
A11: S10 | B11: ACM Digital Library | C11: knowledge graph | D11: A review on the reliability of knowledge graph: from a knowledge representation learning perspective | E11: Yang, Yunxiao; Chen, Jianting; Xiang, Yang | F11: 2024 | G11: Include | H11: Include | I11: No | J11: Include
A12: S100 | B12: ACLWeb | C12: open information extraction; multilingual | D12: Multiˆ2OIE: Multilingual Open Information Extraction Based on Multi-Head Attention with BERT | E12: Ro, Youngbin; Lee, Yukyung; Kang, Pilsung | F12: 2020 | G12: Include | H12: Include | I12: No | J12: Include
A13: S101 | B13: ACLWeb | C13: entity linking; multilingual | D13: Multilingual Autoregressive Entity Linking | E13: De Cao, Nicola; Wu, Ledell; Popat, Kashyap; Artetxe, Mikel; Goyal, Naman; Plekhanov, Mikhail; Zettlemoyer, Luke; Cancedda, Nicola; Riedel, Sebastian; Petroni, Fabio | F13: 2022 | G13: Include | H13: Include | I13: No | J13: Include
... A35: S121 | B35: ACLWeb | C35: Nepali; word embeddings; evaluation; NPVec1 | D35: NPVec1: Word Embeddings for Nepali - Construction and Evaluation | E35: Koirala, Pravesh; Niraula, Nobal B. | F35: 2021 | G35: Include | H35: Include | I35: No | J35: Include
A36: S122 | B36: ACLWeb | C36: rule-based information extraction | D36: Odinson: A Fast Rule-based Information Extraction Framework - ACL Anthology | F36: 2020 | G36: Exclude | H36: Exclude | I36: No | J36: Exclude
A37: S123 | B37: GoogleScholar | C37: open information extraction | D37: Open information extraction from the web | E37: Banko, Michele; Cafarella, Michael J.; Soderland, Stephen; Broadhead, Matt; Etzioni, Oren | F37: 2007 | G37: Include | H37: Include | I37: No | J37: Include
A38: S124 | B38: ACLWeb | C38: open information extraction; Wikipedia | D38: Open Information Extraction Using Wikipedia | F38: 2010 | G38: Exclude | H38: Exclude | I38: No | J38: Exclude
A39: S125 | B39: ACLWeb | C39: open information extraction | D39: Open Language Learning for Information Extraction | E39: Mausam; Schmitz, Michael; Soderland, Stephen; Bart, Robert; Etzioni, Oren | F39: 2012 | G39: Include | H39: Include | I39: No | J39: Include
A40: S126 | B40: ACLWeb | C40: open information extraction; OpenIE6; grid labeling; coordination analysis | D40: OpenIE6: Iterative Grid Labeling and Coordination Analysis for Open Information Extraction | E40: Kolluru, Keshav; Adlakha, Vaibhav; Aggarwal, Samarth; Mausam; Chakrabarti, Soumen | F40: 2020 | G40: Include | H40: Include | I40: No | J40: Include
A41: S127 | B41: GoogleScholar | C41: triple extraction; graph enrichment; large language models; prompting | D41: Organising Knowledge from Text: Prompt-Based Triple Extraction and Graph Enrichment with Large Language Models | G41: Exclude | H41: Exclude | I41: No | J41: Exclude
A42: S128 | B42: ACLWeb | C42: entity and relation extraction; packed levitated marker; span-based | D42: Packed Levitated Marker for Entity and Relation Extraction | E42: Ye, Deming; Lin, Yankai; Li, Peng; Sun, Maosong | F42: 2022 | G42: Include | H42: Include | I42: No | J42: Include
A43: S129 | B43: ACLWeb | C43: Nepali; parsing; Paninian framework; dependency grammar | D43: Parsing Techniques using Paninian Framework on Nepali Language | E43: Yajnik, Archit; Sharma, Dhanapati | F43: 2015 | G43: Include | H43: Include | I43: No | J43: Include
A44: S13 | B44: ACLWeb | C44: open information extraction; large language models; rule-based methods; survey | D44: A Survey on Open Information Extraction from Rule-based Model to Large Language Model | E44: Pai, Liu; Gao, Wenyang; Dong, Wenjie; Ai, Lin; Gong, Ziwei; Huang, Songfang; Zongsheng, Li; Hoque, Ehsan; Hirschberg, Julia; Zhang, Yue | F44: 2024 | G44: Include | H44: Include | I44: No | J44: Include
A45: S130 | B45: ACLWeb | C45: agricultural knowledge graph; multilingual query system; PooRaa-Agri | D45: PooRaa-Agri KG: An agricultural knowledge graph-based simplified multilingual query system | E45: Sivakumar, Nethraa; Srinivasan, Pooja; Kannan, Mrinalini; P, Vijayalakshmi; T, Nagarajan | F45: 2023 | G45: Exclude | H45: Exclude | I45: No | J45: Exclude
A46: S131 | B46: ACLWeb | C46: slot filling; relation extraction; position-aware attention; TACRED | D46: Position-aware Attention and Supervised Data Improve Slot Filling | E46: Zhang, Yuhao; Zhong, Victor; Chen, Danqi; Angeli, Gabor; Manning, Christopher D. | F46: 2017 | G46: Include | H46: Include | I46: No | J46: Include
A47: S132 | B47: GoogleScholar | C47: part-of-speech tagging; Nepali; ambiguity; neural network | D47: Probabilistic and Neural Network Based POS Tagging of Ambiguous Nepali text: A Comparative Study | E47: Pradhan, Ashish; Yajnik, Archit | F47: 2021 | G47: Include | H47: Include | I47: No | J47: Include
A48: S133 | B48: GoogleScholar | C48: named entity recognition; Nepali; prompt engineering; large language models | D48: Prompt Engineering for Nepali NER: Leveraging Hindi-Capable LLMs for Low-Resource Languages | E48: Yadav, Dipendra; Suravee, Sumaiya; Kemnitz, Stefan; Strauss, Tobias; Yordanova, Kristina | F48: 2025 | G48: Include | H48: Include | I48: No | J48: Include
A49: S134 | B49: GoogleScholar | C49: citation chaining | D49: Prompt-based Zero-shot Relation Extraction with Semantic Knowledge Augmentation | E49: Gong, Jiaying; Eldardiry, Hoda | F49: 2024 | G49: Include | H49: Include | I49: No | J49: Include
A50: S135 | B50: ACLWeb | C50: relation extraction; end-to-end; generative models; REBEL; seq2seq | D50: REBEL: Relation Extraction By End-to-end Language generation | E50: Huguet Cabot, Pere-Lluís; Navigli, Roberto | F50: 2021 | G50: Include | H50: Exclude | I50: Yes | J50: Include
A51: S136 | B51: ACLWeb | C51: relation extraction; multilingual dataset; RED-FM | D51: RED FM : a Filtered and Multilingual Relation Extraction Dataset | E51: Huguet Cabot, ‪Pere-Lluís; Tedeschi, Simone; Ngonga Ngomo, Axel-Cyrille; Navigli, Roberto | F51: 2023 | G51: Exclude | H51: Include | I51: Yes | J51: Exclude
A52: S137 | B52: ACM Digital Library | C52: knowledge graph completion; low-resource; adversarial network | D52: Relation Adversarial Network for Low Resource Knowledge Graph Completion | E52: Zhang, Ningyu; Deng, Shumin; Sun, Zhanlin; Chen, Jiaoyan; Zhang, Wei; Chen, Huajun | F52: 2020 | G52: Exclude | H52: Exclude | I52: No | J52: Exclude
A53: S138 | B53: GoogleScholar | C53: low-resource relation extraction; data generation; data selection | D53: Reliable Data Generation and Selection for Low-Resource Relation Extraction | E53: Yu, Junjie; Wang, Xing; Chen, Wenliang | F53: 2024 | G53: Exclude | H53: Exclude | I53: No | J53: Exclude
... A73: S156 | B73: ACLWeb | C73: entity disambiguation; knowledge graphs; large language models | D73: Knowledge Graphs for Enhancing Large Language Models in Entity Disambiguation | E73: Pons, Gerard; Bilalli, Besim; Queralt, Anna | F73: 2025 | G73: Include | H73: Include | I73: No | J73: Include
A74: S157 | B74: IEEE Xplore | C74: keyword generation; Nepali; graph-based extraction; LDA topic modelling | D74: Topic-Wide Keyword Generation From Nepali Documents Through Graph-Based Extraction and LDA Topic Models | E74: Shrestha, Sagar; Pokhrel, Sitaram; Adhikari, Smita | G74: Exclude | H74: Include | I74: Yes | J74: Exclude
A75: S158 | B75: GoogleScholar | C75: knowledge graph lifecycle; knowledge graph population; pipeline; commercial knowledge graph | D75: Towards a Knowledge Graph Lifecycle: A pipeline for the population of a commercial Knowledge Graph | E75: Simsek, Umutcan; Umbrich, Jurgen; Fensel, Dieter | G75: Exclude | H75: Exclude | I75: No | J75: Exclude
A76: S159 | B76: ACLWeb | C76: low-resource relation extraction; benchmark; empirical study | D76: Towards Realistic Low-resource Relation Extraction: A Benchmark with Empirical Baseline Study | E76: Xu, Xin; Chen, Xiang; Zhang, Ningyu; Xie, Xin; Chen, Xi; Chen, Huajun | F76: 2022 | G76: Exclude | H76: Exclude | I76: No | J76: Exclude
A77: S160 | B77: GoogleScholar | C77: knowledge graph construction; RML; mapping generation; large language models | D77: Towards self-configuring Knowledge Graph Construction Pipelines using LLMs - A Case Study with RML | E77: Hofer, Marvin; Frey, Johannes; Rahm, Erhard | F77: 2024 | G77: Exclude | H77: Exclude | I77: No | J77: Exclude
A78: S161 | B78: ACLWeb | C78: relation extraction; tree kernel; parse trees; convolution kernels | D78: Tree Kernel-Based Relation Extraction with Context-Sensitive Structured Parse Tree Information | E78: Zhou, GuoDong; Zhang, Min; Ji, Dong Hong; Zhu, QiaoMing | F78: 2007 | G78: Include | H78: Exclude | I78: Yes | J78: Include
A79: S162 | B79: ACLWeb | C79: joint entity and relation extraction; table-sequence encoders | D79: Two are Better than One: Joint Entity and Relation Extraction with Table-Sequence Encoders | E79: Wang, Jue; Lu, Wei | F79: 2020 | G79: Include | H79: Include | I79: No | J79: Include
A80: S163 | B80: ACLWeb | C80: joint relational triple extraction; unified representation; UniRel | D80: UniRel: Unified Representation and Interaction for Joint Relational Triple Extraction | E80: Tang, Wei; Xu, Benfeng; Zhao, Yuyue; Mao, Zhendong; Liu, Yifeng; Liao, Yong; Xie, Haiyong | F80: 2022 | G80: Exclude | H80: Include | I80: Yes | J80: Exclude
...

Sheet Full_Text_Screening
A1: Study ID | B1: Registar/Database | C1: Keywords | D1: Title | E1: Authors | F1: Year | G1: Reviewer 1 Decision | H1: Reviewer 2 Decision | I1: Conflict | J1: Final Decision | K1: Exclusion Reason
A2: S01 | B2: arXiv | C2: low-resource languages survey ; NLP survey | D2: A Breadth-First Catalog of Text Processing, Speech Processing and Multimodal Research in South Asian Languages | E2: Gupta, Pranav | F2: 2024 | G2: Include | H2: Include | I2: No | J2: Include
A3: S02 | B3: ACM Digital Library | C3: knowledge graph construction; knowledge extraction; survey | D3: A Comprehensive Survey on Automatic Knowledge Graph Construction | E3: Zhong, Lingfeng; Wu, Jia; Li, Qian; Peng, Hao; Wu, Xindong | F3: 2023 | G3: Include | H3: Include | I3: No | J3: Include
A4: S03 | B4: ACLWeb | C4: relation classification; multilingual; low-resource languages; distant supervision | D4: A Data Bootstrapping Recipe for Low-Resource Multilingual Relation Classification | E4: Nag, Arijit; Samanta, Bidisha; Mukherjee, Animesh; Ganguly, Niloy; Chakrabarti, Soumen | F4: 2021 | G4: Include | H4: Include | I4: No | J4: Include
A5: S04 | B5: ACLWeb | C5: knowledge graphs; natural language processing; knowledge extraction; survey | D5: A Decade of Knowledge Graphs in Natural Language Processing: A Survey | E5: Schneider, Phillip; Schopf, Tim; Vladika, Juraj; Galkin, Mikhail; Simperl, Elena; Matthes, Florian | F5: 2022 | G5: Include | H5: Include | I5: No | J5: Include
A6: S05 | B6: ACM Digital Library | C6: anaphora resolution;low-resources; coreference; | D6: A Detailed Study on Anaphora Resolution System for Asian Languages | E6: Prajapati, Priyanka; Goyal, Vishal; Kaur, Kawaljit | F6: 2024 | G6: Exclude | H6: Include | I6: Yes | J6: Exclude
A7: S06 | B7: ACLWeb | C7: entity extraction; relation extraction | D7: A Frustratingly Easy Approach for Entity and Relation Extraction | E7: Zhong, Zexuan; Chen, Danqi | F7: 2021 | G7: Include | H7: Include | I7: No | J7: Include
A8: S07 | B8: ACLWeb | C8: knowledge graph construction; entity extraction; relation extraction | D8: A High Precision Pipeline for Financial Knowledge Graph Construction | E8: Elhammadi, Sarah; V.S. Lakshmanan, Laks; Ng, Raymond; Simpson, Michael; Huai, Baoxing; Wang, Zhefeng; Wang, Lanjun | F8: 2020 | G8: Exclude | H8: Exclude | I8: No | J8: Exclude
A9: S08 | B9: IEEE Xplore | C9: anaphora resolution; Nepali; machine learning; low-resource languages | D9: A Machine Learning Approach to Anaphora Resolution in Nepali Language | E9: Senapati, Apurbalal; Poudyal, Arun; Adhikary, Prithwiraj; Kaushar, Sahana; Mahajan, Anmol; Nath Saha, Baidya | F9: 2020 | G9: Include | H9: Include | I9: No | J9: Include
A10: S09 | B10: ACLWeb | C10: triple extraction; table filling; joint entity and relation extraction | D10: A Novel Global Feature-Oriented Relational Triple Extraction Model based on Table Filling | E10: Ren, Feiliang; Zhang, Longhui; Yin, Shujuan; Zhao, Xiaofeng; Liu, Shilei; Li, Bochao; Liu, Yaduo | F10: 2021 | G10: Exclude | H10: Include | I10: Yes | J10: Exclude
A11: S10 | B11: ACM Digital Library | C11: knowledge graph | D11: A review on the reliability of knowledge graph: from a knowledge representation learning perspective | E11: Yang, Yunxiao; Chen, Jianting; Xiang, Yang | F11: 2024 | G11: Exclude | H11: Exclude | I11: No | J11: Exclude
A12: S100 | B12: ACLWeb | C12: open information extraction; multilingual | D12: Multiˆ2OIE: Multilingual Open Information Extraction Based on Multi-Head Attention with BERT | E12: Ro, Youngbin; Lee, Yukyung; Kang, Pilsung | F12: 2020 | G12: Include | H12: Include | I12: No | J12: Include
A13: S101 | B13: ACLWeb | C13: entity linking; multilingual | D13: Multilingual Autoregressive Entity Linking | E13: De Cao, Nicola; Wu, Ledell; Popat, Kashyap; Artetxe, Mikel; Goyal, Naman; Plekhanov, Mikhail; Zettlemoyer, Luke; Cancedda, Nicola; Riedel, Sebastian; Petroni, Fabio | F13: 2022 | G13: Include | H13: Include | I13: No | J13: Include
... A114: S99 | B114: GoogleScholar | C114: relation extraction; distant supervision; latent variable model; weak supervision | D114: Modeling Relations and Their Mentions without Labeled Text | E114: Riedel, Sebastian; Yao, Limin; McCallum, Andrew | F114: 2010 | G114: Include | H114: Include | I114: No | J114: Include

Sheet Cohen_Kappa
A1: Inter-Annotator Agreement: Cohen's Kappa (Reviewer 1 vs Reviewer 2)
A2: All counts are live COUNTIFS formulas on the screening sheets (columns G and H), so they update if decisions change.
A4: Task 1: Title & Abstract Screening
B5: R2: Include | C5: R2: Exclude | D5: Total
A6: R1: Include | B6: =COUNTIFS(Title_Abstract_Screening!$G$2:$G$172,"Include",Title_Abstract_Screening!$H$2:$H$172,"Include") -> 103 | C6: =COUNTIFS(Title_Abstract_Screening!$G$2:$G$172,"Include",Title_Abstract_Screening!$H$2:$H$172,"Exclude") -> 11 | D6: =SUM(B6:C6) -> 114
A7: R1: Exclude | B7: =COUNTIFS(Title_Abstract_Screening!$G$2:$G$172,"Exclude",Title_Abstract_Screening!$H$2:$H$172,"Include") -> 9 | C7: =COUNTIFS(Title_Abstract_Screening!$G$2:$G$172,"Exclude",Title_Abstract_Screening!$H$2:$H$172,"Exclude") -> 48 | D7: =SUM(B7:C7) -> 57
A8: Total | B8: =SUM(B6:B7) -> 112 | C8: =SUM(C6:C7) -> 59 | D8: =SUM(D6:D7) -> 171
A10: N (studies rated by both) | B10: =D8 -> 171
A11: Observed agreement (Po) | B11: =(B6+C7)/D8 -> 0.88304094
A12: Expected agreement by chance (Pe) | B12: =(D6*B8+D7*C8)/D8^2 -> 0.55165692
A13: Cohen's Kappa | B13: =(B11-B12)/(1-B12) -> 0.73913043
A16: Task 2: Full-Text Screening
B17: R2: Include | C17: R2: Exclude | D17: Total
A18: R1: Include | B18: =COUNTIFS(Full_Text_Screening!$G$2:$G$114,"Include",Full_Text_Screening!$H$2:$H$114,"Include") -> 88 | C18: =COUNTIFS(Full_Text_Screening!$G$2:$G$114,"Include",Full_Text_Screening!$H$2:$H$114,"Exclude") -> 2 | D18: =SUM(B18:C18) -> 90
A19: R1: Exclude | B19: =COUNTIFS(Full_Text_Screening!$G$2:$G$114,"Exclude",Full_Text_Screening!$H$2:$H$114,"Include") -> 7 | C19: =COUNTIFS(Full_Text_Screening!$G$2:$G$114,"Exclude",Full_Text_Screening!$H$2:$H$114,"Exclude") -> 16 | D19: =SUM(B19:C19) -> 23
A20: Total | B20: =SUM(B18:B19) -> 95 | C20: =SUM(C18:C19) -> 18 | D20: =SUM(D18:D19) -> 113
A22: N (studies rated by both) | B22: =D20 -> 113
A23: Observed agreement (Po) | B23: =(B18+C19)/D20 -> 0.92035398
A24: Expected agreement by chance (Pe) | B24: =(D18*B20+D19*C20)/D20^2 -> 0.70201269
A25: Cohen's Kappa | B25: =(B23-B24)/(1-B24) -> 0.73272011
A30: Kappa = (Po - Pe) / (1 - Pe)
